# Generated by Django 3.0.4 on 2020-05-14 10:01

import django.contrib.auth.validators
from django.db import migrations, models
import phonenumber_field.modelfields


class Migration(migrations.Migration):

    dependencies = [
        ('auth', '0011_update_proxy_permissions'),
        ('account', '0034_auto_20200507_0628'),
    ]

    operations = [
        migrations.AddField(
            model_name='user',
            name='first_name',
            field=models.CharField(blank=True, max_length=150, null=True),
        ),
        migrations.AddField(
            model_name='user',
            name='last_name',
            field=models.CharField(blank=True, max_length=150, null=True),
        ),
        migrations.AlterField(
            model_name='user',
            name='groups',
            field=models.ManyToManyField(blank=True, null=True, to='auth.Group'),
        ),
        migrations.AlterField(
            model_name='user',
            name='phone',
            field=phonenumber_field.modelfields.PhoneNumberField(blank=True, max_length=128, null=True, region=None, unique=True),
        ),
        migrations.AlterField(
            model_name='user',
            name='username',
            field=models.CharField(error_messages={'unique': 'A user with that username already exists.'}, help_text='Required. 150 characters or fewer. Letters, digits and @/./+/-/_ only.', max_length=150, unique=True, validators=[django.contrib.auth.validators.UnicodeUsernameValidator()], verbose_name='username'),
        ),
    ]
